2025-05-30 10:55:36,606 [INFO] concord.llm.prompts: Loaded external template: v1.1-enzyme
2025-05-30 10:55:36,607 [INFO] concord.llm.prompts: Loaded external template: v2
2025-05-30 10:55:36,607 [INFO] concord.llm.prompts: Loaded external template: v2.1
2025-05-30 10:55:36,607 [INFO] concord.llm.prompts: Loaded external template: v3.0-CoT
2025-05-30 10:55:36,607 [INFO] concord.llm.prompts: Loaded external template: v3.1-CoT
2025-05-30 10:55:36,607 [INFO] concord.llm.prompts: Loaded external template: v1.2-general
2025-05-30 10:55:36,608 [INFO] concord.llm.prompts: Loaded external template: v1.3-test
2025-05-30 10:55:36,608 [INFO] concord.llm.prompts: Loaded external template: v1.1-phage
2025-05-30 10:55:36,608 [INFO] concord.llm.prompts: Loaded external template: v1.0
2025-05-30 10:55:36,608 [INFO] concord.llm.prompts: Loaded external template: v3.0
2025-05-30 10:55:36,608 [INFO] concord.llm.prompts: Loaded external template: v1.1-general
2025-05-30 10:55:36,609 [INFO] concord.llm.prompts: Loaded external template: v3.1
2025-05-30 10:55:36,609 [INFO] concord.llm.prompts: Loaded external template: v0.0_bug_test
2025-05-30 10:55:36,613 [INFO] concord.llm.argo_gateway: ArgoGatewayClient initialised | model=gpt4olatest env=prod timeout=30.0s url=https://apps.inside.anl.gov/argoapi/api/v1/resource/chat/
âœ“ Argo Gateway API reachable
2025-05-30 10:55:37,508 [ERROR] concord.pipeline: Failed to read input file eval/datasets/Benchmark_subset__24_pairs_v1.tsv: [Errno 2] No such file or directory: 'eval/datasets/Benchmark_subset__24_pairs_v1.tsv'
2025-05-30 10:55:37,508 [ERROR] concord.pipeline: run_file failed: Invalid input file: [Errno 2] No such file or directory: 'eval/datasets/Benchmark_subset__24_pairs_v1.tsv'
2025-05-30 10:55:37,512 [ERROR] concord.cli: Error processing file: Invalid input file: [Errno 2] No such file or directory: 'eval/datasets/Benchmark_subset__24_pairs_v1.tsv'
Traceback (most recent call last):
  File "/Users/jplfaria/repos/CONCORDIA/concord/pipeline.py", line 356, in run_file
    pd.read_csv(file_path, engine="python")
  File "/Users/jplfaria/Library/Caches/pypoetry/virtualenvs/concordia-vKLIi626-py3.11/lib/python3.11/site-packages/pandas/io/parsers/readers.py", line 1026, in read_csv
    return _read(filepath_or_buffer, kwds)
           ^^^^^^^^^^^^^^^^^^^^^^^^^^^^^^^
  File "/Users/jplfaria/Library/Caches/pypoetry/virtualenvs/concordia-vKLIi626-py3.11/lib/python3.11/site-packages/pandas/io/parsers/readers.py", line 620, in _read
    parser = TextFileReader(filepath_or_buffer, **kwds)
             ^^^^^^^^^^^^^^^^^^^^^^^^^^^^^^^^^^^^^^^^^^
  File "/Users/jplfaria/Library/Caches/pypoetry/virtualenvs/concordia-vKLIi626-py3.11/lib/python3.11/site-packages/pandas/io/parsers/readers.py", line 1620, in __init__
    self._engine = self._make_engine(f, self.engine)
                   ^^^^^^^^^^^^^^^^^^^^^^^^^^^^^^^^^
  File "/Users/jplfaria/Library/Caches/pypoetry/virtualenvs/concordia-vKLIi626-py3.11/lib/python3.11/site-packages/pandas/io/parsers/readers.py", line 1880, in _make_engine
    self.handles = get_handle(
                   ^^^^^^^^^^^
  File "/Users/jplfaria/Library/Caches/pypoetry/virtualenvs/concordia-vKLIi626-py3.11/lib/python3.11/site-packages/pandas/io/common.py", line 873, in get_handle
    handle = open(
             ^^^^^
FileNotFoundError: [Errno 2] No such file or directory: 'eval/datasets/Benchmark_subset__24_pairs_v1.tsv'

The above exception was the direct cause of the following exception:

Traceback (most recent call last):
  File "/Users/jplfaria/repos/CONCORDIA/concord/cli.py", line 177, in concord
    out = run_file(
          ^^^^^^^^^
  File "/Users/jplfaria/repos/CONCORDIA/concord/pipeline.py", line 362, in run_file
    raise ValueError(f"Invalid input file: {e}") from e
ValueError: Invalid input file: [Errno 2] No such file or directory: 'eval/datasets/Benchmark_subset__24_pairs_v1.tsv'
Error processing file: Invalid input file: [Errno 2] No such file or directory: 
'eval/datasets/Benchmark_subset__24_pairs_v1.tsv'
2025-05-30 10:55:37,513 [ERROR] concord.cli: Unhandled exception: 1
Traceback (most recent call last):
  File "/Users/jplfaria/repos/CONCORDIA/concord/pipeline.py", line 356, in run_file
    pd.read_csv(file_path, engine="python")
  File "/Users/jplfaria/Library/Caches/pypoetry/virtualenvs/concordia-vKLIi626-py3.11/lib/python3.11/site-packages/pandas/io/parsers/readers.py", line 1026, in read_csv
    return _read(filepath_or_buffer, kwds)
           ^^^^^^^^^^^^^^^^^^^^^^^^^^^^^^^
  File "/Users/jplfaria/Library/Caches/pypoetry/virtualenvs/concordia-vKLIi626-py3.11/lib/python3.11/site-packages/pandas/io/parsers/readers.py", line 620, in _read
    parser = TextFileReader(filepath_or_buffer, **kwds)
             ^^^^^^^^^^^^^^^^^^^^^^^^^^^^^^^^^^^^^^^^^^
  File "/Users/jplfaria/Library/Caches/pypoetry/virtualenvs/concordia-vKLIi626-py3.11/lib/python3.11/site-packages/pandas/io/parsers/readers.py", line 1620, in __init__
    self._engine = self._make_engine(f, self.engine)
                   ^^^^^^^^^^^^^^^^^^^^^^^^^^^^^^^^^
  File "/Users/jplfaria/Library/Caches/pypoetry/virtualenvs/concordia-vKLIi626-py3.11/lib/python3.11/site-packages/pandas/io/parsers/readers.py", line 1880, in _make_engine
    self.handles = get_handle(
                   ^^^^^^^^^^^
  File "/Users/jplfaria/Library/Caches/pypoetry/virtualenvs/concordia-vKLIi626-py3.11/lib/python3.11/site-packages/pandas/io/common.py", line 873, in get_handle
    handle = open(
             ^^^^^
FileNotFoundError: [Errno 2] No such file or directory: 'eval/datasets/Benchmark_subset__24_pairs_v1.tsv'

The above exception was the direct cause of the following exception:

Traceback (most recent call last):
  File "/Users/jplfaria/repos/CONCORDIA/concord/cli.py", line 177, in concord
    out = run_file(
          ^^^^^^^^^
  File "/Users/jplfaria/repos/CONCORDIA/concord/pipeline.py", line 362, in run_file
    raise ValueError(f"Invalid input file: {e}") from e
ValueError: Invalid input file: [Errno 2] No such file or directory: 'eval/datasets/Benchmark_subset__24_pairs_v1.tsv'

During handling of the above exception, another exception occurred:

Traceback (most recent call last):
  File "/Users/jplfaria/repos/CONCORDIA/concord/cli.py", line 192, in concord
    raise typer.Exit(1)
click.exceptions.Exit: 1
Error: 1
[1/2] Running MODE=zero-shot, PROMPT=v1.0, SIM_HINT=no -> eval/results/benchmark_run_20250530_105534/gpt4olatest/gpt4olatest_v1.0_zero.csv
Traceback (most recent call last):
  File "/Users/jplfaria/repos/CONCORDIA/eval/scripts/benchmark_runner.py", line 87, in <module>
    main()
  File "/Users/jplfaria/repos/CONCORDIA/eval/scripts/benchmark_runner.py", line 83, in main
    subprocess.run(cmd, check=True)
  File "/Users/jplfaria/miniconda3/lib/python3.11/subprocess.py", line 571, in run
    raise CalledProcessError(retcode, process.args,
subprocess.CalledProcessError: Command '['concord', 'eval/datasets/Benchmark_subset__24_pairs_v1.tsv', '--mode', 'zero-shot', '--llm-model', 'gpt4olatest', '--prompt-ver', 'v1.0', '--llm-batch-size', '20', '--output', 'eval/results/benchmark_run_20250530_105534/gpt4olatest/gpt4olatest_v1.0_zero.csv', '--cfg', 'config.yaml']' returned non-zero exit status 1.
